Workbook

Sheet Creator DNA
A1: # | B1: Category | C1: Creator | D1: Country | E1: Platforms | F1: Format | G1: Vibe | H1: Tone | I1: Energy (1-5) | J1: Pacing & edit | K1: Camera & framing | L1: Lighting & grade | M1: Voice & delivery | N1: Target age | O1: Target audience | P1: Hook pattern | Q1: Signature move | R1: Best fit for Klaus | S1: Confidence | T1: Verify notes | U1: Batch
A2: 1 | B2: Skits / comedy / 2-3 person | C2: Adam Waheed | D2: USA | E2: TikTok, IG, YouTube | F2: Ensemble skit | G2: Big-budget sitcom on a phone | H2: Playful, family-friendly slapstick | I2: 5 | J2: Fast 1-2s cuts, reaction inserts, SFX hits | K2: Stable multi-angle coverage, wide to close | L2: Bright, evenly lit, saturated | M2: Loud, exaggerated characters | N2: 13-34 | O2: Broad US/global mainstream | P2: Absurd situation in frame 1 | Q2: Physical gag + cast reaction shot | R2: Physio Spot ensemble skits | S2: Medium | T2: Confirm current posting cadence | U2: Wk4 skits+ads anchors
A3: 2 | B3: Skits / comedy / 2-3 person | C3: Druski | D3: USA | E3: IG, TikTok, YouTube | F3: 2-3 person / character | G3: Improvised cringe mockumentary | H3: Awkward, roasting | I3: 4 | J3: Lets awkward pauses breathe; longer takes | K3: Handheld doc-style | L3: Natural / practical | M3: Deadpan + improvised characters | N3: 16-34 | O3: US urban, hip-hop culture fans | P3: Character intro mid-scene | Q3: Escalating awkwardness, celebrity cameos | R3: Physio Spot 2-person cringe skits | S3: Medium | U3: Wk4 skits+ads anchors
A4: 3 | B4: Skits / comedy / 2-3 person | C4: Chef Pierce | D4: USA | E4: TikTok | F4: POV duo skits | G4: Fast situational POV | H4: Playful | I4: 4 | J4: Quick cuts, trending audio | K4: Phone POV | L4: Natural | M4: Casual | N4: 13-24 | O4: US Gen Z | P4: POV text overlay | Q4: DNA placeholder | R4: TBD after watch | S4: Low | T4: DNA guessed - derive from vidIQ watch | U4: Month 2+
A5: 4 | B5: Skits / comedy / 2-3 person | C5: Darryl Mayes | D5: USA | E5: TikTok | F5: POV skits | G5: Situational POV | H5: Playful | I5: 4 | J5: Quick cuts | K5: Phone POV | L5: Natural | M5: Casual | N5: 13-24 | O5: US Gen Z | P5: POV text overlay | Q5: DNA placeholder | R5: TBD after watch | S5: Low | T5: Country + DNA to verify | U5: Month 2+
A6: 5 | B6: Skits / comedy / 2-3 person | C6: Jaden Williams | D6: USA | E6: TikTok, YouTube Shorts | F6: Solo characters | G6: Kid-relatable character POVs | H6: Wholesome, silly | I6: 4 | J6: Fast cuts, voice swaps | K6: Phone, front-facing | L6: Bright indoor | M6: Character voices | N6: 10-20 | O6: Gen Alpha / young Gen Z | P6: 'POV:' setup | Q6: Plays multiple kid archetypes | R6: Low fit (very young audience) | S6: Low | T6: Country + audience to verify | U6: Month 2+
A7: 6 | B7: Skits / comedy / 2-3 person | C7: DTay Known | D7: USA | E7: TikTok, IG | F7: Character skits | G7: Hood-relatable characters | H7: Roasting, loud | I7: 5 | J7: Fast cuts | K7: Phone | L7: Natural | M7: Loud characters | N7: 16-30 | O7: US urban Gen Z | P7: Instant character entrance | Q7: DNA placeholder | R7: TBD after watch | S7: Low | T7: DNA guessed - derive from watch | U7: Month 2+
A8: 7 | B8: Skits / comedy / 2-3 person | C8: FunnyMike | D8: USA | E8: TikTok, YouTube | F8: High-energy skits / pranks | G8: Chaotic hype | H8: Loud, chaotic | I8: 5 | J8: Very fast, prank reveals | K8: Handheld | L8: Mixed natural | M8: Shouting, hype | N8: 13-24 | O8: US Gen Z | P8: Chaos in frame 1 | Q8: DNA placeholder | R8: TBD after watch | S8: Low | T8: DNA guessed - derive from watch | U8: Month 2+
A9: 8 | B9: Skits / comedy / 2-3 person | C9: Brittany Broski | D9: USA | E9: TikTok, YouTube | F9: Reaction-face comedy | G9: Chaotic-relatable internet bestie | H9: Absurd, self-deprecating | I9: 4 | J9: Talk + reaction, snap punch-ins | K9: Front-facing selfie, tight | L9: Ring light / soft indoor | M9: Elastic face, theatrical voices | N9: 18-34 | O9: US Gen Z + millennial women, pop culture | P9: A face reaction | Q9: The face IS the punchline | R9: Reaction inserts in any skit | S9: High | U9: Wk4 skits+ads anchors
A10: 9 | B10: Skits / comedy / 2-3 person | C10: Liza Koshy | D10: USA | E10: TikTok, YouTube, IG | F10: Multi-character | G10: Hyper, colourful wordplay | H10: Wholesome, punny | I10: 5 | J10: Very fast jump cuts, plays all roles | K10: Front-facing, tight | L10: High-key, saturated colour | M10: Rapid puns, voices | N10: 13-29 | O10: Global teens / young adults | P10: Pun or character opener | Q10: Rapid-fire puns + playing every role | R10: GenZ-energy Power Protein promos | S10: High | U10: Wk4 skits+ads anchors
A11: 10 | B11: Skits / comedy / 2-3 person | C11: Mr Funny (Sabinus) | D11: Nigeria | E11: IG, TikTok, YouTube | F11: Short skit | G11: Hapless everyman in Lagos life | H11: Slapstick, pity humour | I11: 4 | J11: Short scenes, payoff at the end | K11: Simple handheld, street settings | L11: Natural daylight, ungraded | M11: Nigerian Pidgin, expressive | N11: 16-40 | O11: Nigeria + African diaspora | P11: Everyday situation setup | Q11: The guy who always loses | R11: Template for 'unlucky patient' skits | S11: Medium | U11: Wk4 skits+ads anchors
A12: 11 | B12: Skits / comedy / 2-3 person | C12: Munya Chawawa | D12: UK | E12: IG, TikTok, YouTube | F12: Character satire | G12: Sharp topical satire | H12: Witty, ironic, political | I12: 3 | J12: TV-sketch tight edit | K12: Polished; mock-news / music-video framing | L12: TV quality, styled | M12: Accents, characters, wordplay | N12: 18-40 | O12: UK urban, politically aware millennials | P12: Topical news hook | Q12: Character parody of current events | R12: SG politics channel + Physio Spot satire | S12: High | U12: Wk1 pilot
A13: 12 | B13: Skits / comedy / 2-3 person | C13: Puspa Wafiy | D13: Malaysia | E13: TikTok, IG | F13: Couple sketch | G13: Wholesome Malay couple banter | H13: Light, relatable | I13: 3 | J13: Short, music/dance mixed in | K13: Phone, home settings | L13: Natural home light | M13: Casual Malay | N13: 18-40 | O13: Malaysia, Malay-speaking | P13: Couple situation | Q13: Husband-and-wife dynamic | R13: Couple-format pelvic health skits | S13: Medium | U13: Wk4 skits+ads anchors
A14: 13 | B14: Ads / UGC / product | C14: @ugcbymackenzie | D14: USA | E14: TikTok | F14: 5 ad formats from 1 product | G14: Clean aesthetic UGC | H14: Friendly, persuasive | I14: 3 | J14: 1-2s cuts, B-roll + talking | K14: Phone, product close-ups, hands | L14: Soft window light, bright | M14: Casual creator VO | N14: 18-44 (brand-dependent) | O14: US shoppers, women-skewed | P14: Problem statement | Q14: One product -> 5 angles | R14: Power Protein + PeachForm ad variants | S14: Medium | T14: Country to verify | U14: Month 2+
A15: 14 | B15: Ads / UGC / product | C15: @sarahbanks.ugc | D15: USA | E15: TikTok | F15: At-home UGC | G15: Simple, approachable | H15: Helpful | I15: 3 | J15: Simple cuts | K15: Phone, home | L15: Natural home light | M15: Casual | N15: 18-40 | O15: US shoppers | P15: Show-the-product opener | Q15: Low-budget at-home recipe | R15: Cheap UGC template | S15: Low | T15: Country + DNA to verify | U15: Month 2+
A16: 15 | B16: Ads / UGC / product | C16: Stepful | D16: USA | E16: TikTok (Spark Ads) | F16: Clinical testimonial | G16: Aspirational career testimonial | H16: Earnest, credible | I16: 3 | J16: Medium pace, fact text overlays | K16: Real clinical setting, mid shots | L16: Clinic / natural | M16: Real student voice | N16: 18-35 | O16: US career changers, women-skewed | P16: Concrete claim on screen | Q16: Scrubs + proof stats | R16: Physio Spot patient/clinic testimonials | S16: Medium | U16: Wk4 skits+ads anchors
A17: 16 | B17: Ads / UGC / product | C17: Caseharden | D17: USA | E17: TikTok (Spark Ads) | F17: Founder-led | G17: Maker credibility | H17: Direct, no-nonsense | I17: 3 | J17: Simple, captioned | K17: Founder to camera | L17: Workshop natural | M17: Founder's own voice | N17: 25-54 | O17: US men, gear/EDC buyers | P17: Founder states the problem | Q17: Founder as the face | R17: Physio Niklaus founder ads | S17: Medium | T17: Country + audience to verify | U17: Month 2+
A18: 17 | B18: Ads / UGC / product | C18: 7 Brew | D18: USA | E18: TikTok (Spark Ads) | F18: In-car selfie UGC | G18: Bubbly drive-thru moment | H18: Fun, casual | I18: 4 | J18: One take + caption | K18: Phone selfie in car | L18: Car daylight | M18: Chatty | N18: 16-28 | O18: US Gen Z women, Midwest/South | P18: Relatable caption | Q18: Product in hand in the car | R18: Power Protein drink ads | S18: Medium | U18: Month 2+
A19: 18 | B19: Ads / UGC / product | C19: Chipotle #GuacDance | D19: USA | E19: TikTok | F19: Challenge | G19: Participatory dance trend | H19: Playful | I19: 5 | J19: Music-synced | K19: Creator-shot, varied | L19: Varied | M19: Music-led | N19: 13-24 | O19: US Gen Z | P19: The dance itself | Q19: Free-product incentive to join | R19: Power Protein launch challenge | S19: High | U19: Month 2+
A20: 19 | B20: Ads / UGC / product | C20: Duolingo | D20: USA | E20: TikTok | F20: Brand-as-creator | G20: Unhinged mascot | H20: Chaotic, self-aware, meme-literate | I20: 5 | J20: Trend-native, reacts within hours | K20: Phone, mascot costume in office | L20: Flat office light | M20: Mascot antics, trend audio | N20: 13-24 | O20: Global Gen Z | P20: Absurd mascot behaviour | Q20: Brand acting like a creator | R20: Physio Spot/TITAN brand voice ideas | S20: High | U20: Wk4 skits+ads anchors
A21: 20 | B21: Ads / UGC / product | C21: Liquid Death | D21: USA | E21: TikTok, YouTube | F21: Absurdist brand comedy | G21: Metal/punk parody | H21: Dark humour, mock-serious | I21: 4 | J21: Commercial-parody production | K21: Cinematic | L21: High-production, dramatic | M21: Deadpan narrator | N21: 21-40 | O21: US men, alt/millennial | P21: Overblown premise | Q21: Treats water like heavy metal | R21: Edgy Physio Spot campaigns | S21: High | U21: Wk4 skits+ads anchors
A22: 21 | B22: Ads / UGC / product | C22: Scrub Daddy | D22: USA | E22: TikTok | F22: Product-as-character | G22: Goofy live demos | H22: Wholesome, goofy | I22: 4 | J22: Fast demos, comment replies | K22: Phone, product close-ups | L22: Bright | M22: Playful | N22: 18-45 | O22: Broad households | P22: Satisfying demo | Q22: Product personality + replies to comments | R22: PeachForm/Power Protein demo ads | S22: Medium | U22: Wk5 depth
A23: 22 | B23: Ads / UGC / product | C23: Thanonchai Sornsriwichai | D23: Thailand | E23: YouTube (brand films) | F23: Emotional 'sadvert' | G23: Short-film tearjerker | H23: Sentimental | I23: 1 | J23: Slow, 2-4 min, twist ending | K23: Cinematic, composed | L23: Warm filmic grade | M23: Minimal dialogue, music-led | N23: All ages | O23: Broad Asia | P23: Ordinary person's struggle | Q23: Emotional twist, brand only at the end | R23: Physio Spot patient-journey films | S23: High | U23: Wk4 skits+ads anchors
A24: 23 | B24: Ads / UGC / product | C24: Frank Body | D24: Australia | E24: IG, TikTok | F24: Before/after UGC | G24: Cheeky 'babe' brand voice | H24: Flirty, playful | I24: 3 | J24: Quick before/after cuts | K24: Phone UGC | L24: Bright pastel/pink | M24: Brand speaks like a friend | N24: 18-34 | O24: Women, global | P24: Result shot first | Q24: Cheeky copy + visible results | R24: PeachForm results ads | S24: Medium | U24: Wk5 depth
A25: 24 | B25: Ads / UGC / product | C25: Night Owl Cinematics | D25: Singapore | E25: YouTube, IG, TikTok | F25: Branded ensemble skit | G25: Local sitcom with a sponsor | H25: Comedic, Singlish | I25: 4 | J25: Sitcom pacing | K25: Multi-cam cinematic | L25: Bright commercial | M25: Singlish characters | N25: 16-40 | O25: Singaporeans | P25: Relatable local situation | Q25: Brand woven into a sketch | R25: Localised SG Physio Spot skits | S25: Medium | U25: Wk1 pilot
A26: 25 | B26: Yapping / storytelling / talking-head | C26: Jun Yuh | D26: USA | E26: TikTok, IG | F26: Talking-head yap | G26: Calm, intimate, introspective | H26: Warm, encouraging | I26: 2 | J26: Few cuts; one continuous thought; soft music bed | K26: Forward-facing, eye-level medium close-up, tripod | L26: Soft natural key, warm | M26: Mellow, rhythmic, deliberate emphasis | N26: 18-34 | O26: Aspiring creators, self-improvement | P26: Relatable pain line | Q26: Storytelling frameworks + silent-film reels | R26: Physio Niklaus calm education yaps | S26: High | U26: Wk1 pilot
A27: 26 | B27: Yapping / storytelling / talking-head | C27: Chandler Lee | D27: USA | E27: TikTok | F27: Authority yap | G27: Polished coach | H27: Confident, instructive | I27: 3 | J27: Moderate cuts, captions | K27: Front-facing medium close-up | L27: Bright clean | M27: Clear, confident | N27: 22-40 | O27: Women entrepreneurs/creators | P27: Bold claim | Q27: Authority positioning | R27: Physio Spot expert positioning | S27: Medium | U27: Wk2 yapping
A28: 27 | B28: Yapping / storytelling / talking-head | C28: Jessi Jean | D28: USA | E28: TikTok | F28: Natural yap | G28: Unfiltered best-friend chat | H28: Candid | I28: 3 | J28: Minimal edit | K28: Selfie, close | L28: Natural indoor | M28: Chatty, natural | N28: 20-40 | O28: Women | P28: Story starts mid-thought | Q28: Pure unscripted delivery | R28: Casual Physio Niklaus updates | S28: Low | T28: DNA to verify | U28: Month 2+
A29: 28 | B29: Yapping / storytelling / talking-head | C29: Mia McGrath | D29: USA | E29: TikTok, IG | F29: Lightly scripted yap | G29: Frugal-chic lifestyle | H29: Friendly, practical | I29: 3 | J29: Light cuts | K29: Front-facing | L29: Soft natural | M29: Conversational | N29: 22-40 | O29: Women, personal finance/style | P29: Relatable money/style hook | Q29: Scripted-but-natural | R29: heal360 lifestyle content | S29: Medium | U29: Wk2 yapping
A30: 29 | B30: Yapping / storytelling / talking-head | C30: Kimberly Dang | D30: USA | E30: TikTok | F30: Episodic advice | G30: Communication coach | H30: Supportive | I30: 3 | J30: Episodic format | K30: Front-facing | L30: Clean | M30: Articulate | N30: 20-35 | O30: Young professionals | P30: 'Today's episode is for...' | Q30: Episode framing | R30: Series-format physio tips | S30: Low | T30: DNA to verify | U30: Month 2+
A31: 30 | B31: Yapping / storytelling / talking-head | C31: Alex Hormozi | D31: USA | E31: TikTok, IG, YouTube | F31: Business sermon | G31: Intense, dense value | H31: Blunt, contrarian | I31: 4 | J31: Very fast; every pause cut; word-by-word bold captions; graphics | K31: Tight medium close-up, studio/gym | L31: High-contrast studio | M31: Deep, rapid, punchy | N31: 22-45 | O31: Men-skewed entrepreneurs | P31: Contrarian claim | Q31: Dense captions + numbers | R31: TITAN business channel | S31: High | U31: Wk2 yapping
A32: 31 | B32: Yapping / storytelling / talking-head | C32: Mel Robbins | D32: USA | E32: IG, TikTok, YouTube | F32: Motivational talk | G32: Warm tough-love | H32: Empathetic, practical | I32: 3 | J32: Podcast/stage clips | K32: Mid shots, studio/stage | L32: Polished studio | M32: Raspy, conversational | N32: 30-60 | O32: Women-skewed | P32: 'If you...' hook | Q32: Simple rule people can use today | R32: heal360 mindset/recovery content | S32: High | U32: Wk2 yapping
A33: 32 | B33: Yapping / storytelling / talking-head | C33: Gary Vaynerchuk | D33: USA | E33: All platforms | F33: Raw hype | G33: Unpolished hustle | H33: Loud, direct | I33: 5 | J33: Clips from keynotes/vlogs, doc-style | K33: Handheld documentary | L33: Mixed natural | M33: Loud NY, unfiltered | N33: 18-40 | O33: Aspiring entrepreneurs | P33: Hard truth opener | Q33: Volume of raw clips | R33: TITAN operator content | S33: High | U33: Wk2 yapping
A34: 33 | B34: Yapping / storytelling / talking-head | C34: Steven Bartlett | D34: UK | E34: YouTube, TikTok, IG | F34: Podcast-clip storytelling | G34: Moody, emotional depth | H34: Earnest | I34: 2 | J34: Clips of key guest moments | K34: Dark studio, multi-cam | L34: Low-key dramatic | M34: Calm British | N34: 20-45 | O34: Global self-improvement | P34: Guest's shocking stat/quote | Q34: Moody studio + emotional moment | R34: Future Physio Niklaus podcast | S34: High | U34: Wk2 yapping
A35: 34 | B35: Yapping / storytelling / talking-head | C35: Ho Nguyen Minh Khang | D35: Vietnam | E35: TikTok | F35: Educator storytelling | G35: Nostalgic school life | H35: Warm, nostalgic | I35: 3 | J35: Story-led | K35: Front-facing / classroom | L35: Natural | M35: Teacher voice, Vietnamese | N35: 13-25 | O35: Vietnamese youth | P35: School-memory hook | Q35: Nostalgia + lesson | R35: HCMC docuseries tone | S35: Low | T35: DNA to verify | U35: Month 2+
A36: 35 | B36: Yapping / storytelling / talking-head | C36: Jerome Polin | D36: Indonesia | E36: YouTube, TikTok, IG | F36: Edu-vlog | G36: Upbeat smart-friend | H36: Positive, curious | I36: 4 | J36: Vlog pace with explainers | K36: Mixed vlog + talking head | L36: Bright | M36: Energetic Bahasa Indonesia | N36: 13-25 | O36: Indonesian students | P36: Curious question | Q36: Math/Japan life explained simply | R36: Education explainer format | S36: Medium | U36: Wk2 yapping
A37: 36 | B37: Yapping / storytelling / talking-head | C37: Lukeychan | D37: Singapore | E37: TikTok | F37: Commentary yap | G37: Witty SG society takes | H37: Light, observational | I37: 3 | J37: Light cuts | K37: Front-facing | L37: Natural indoor | M37: Singaporean English | N37: 18-35 | O37: Singaporeans | P37: Relatable SG situation | Q37: Relationship/society commentary | R37: SG audience Physio Spot yaps | S37: Medium | U37: Wk2 yapping
A38: 37 | B38: Streamers & clip edits | C38: Kai Cenat | D38: USA | E38: Twitch, YouTube clips, TikTok | F38: Streamer (source energy) | G38: Loud, chaotic hangout | H38: Hype, unpredictable | I38: 5 | J38: Clip channels: hard cut into the peak, bold animated captions, guest-reaction cutaways | K38: Webcam + room cam, multi-person | L38: Bright RGB streamer room | M38: Shouting reactions, catchphrases | N38: 13-24 | O38: US/global Gen Z gaming + culture | P38: Peak reaction in frame 1 | Q38: Surprise guests + over-the-top reactions | R38: Energy template for Power Protein/PeachForm hype clips | S38: High | U38: Wk3 streamers
A39: 38 | B39: Streamers & clip edits | C39: IShowSpeed | D39: USA | E39: YouTube, TikTok clips | F39: Streamer (source energy) | G39: Unhinged global IRL tours | H39: Chaotic, wholesome-chaotic | I39: 5 | J39: Clip channels: phonk music, skull emoji, dramatic captions ('W Speed') | K39: Handheld IRL + webcam | L39: Natural IRL / RGB room | M39: Screaming, barking, catchphrases | N39: 10-24 | O39: Global Gen Z / Gen Alpha | P39: Freakout or stunt | Q39: Physical chaos + fan interactions | R39: Ironic 'W' edit format for any brand | S39: High | U39: Wk3 streamers
A40: 39 | B40: Streamers & clip edits | C40: Adin Ross | D40: USA | E40: Kick, YouTube clips | F40: Streamer (source energy) | G40: Celebrity-guest drama | H40: Provocative | I40: 4 | J40: Clip channels: guest-reaction zooms, drama captions | K40: Webcam + guest cam | L40: RGB studio | M40: Banter, provocation | N40: 16-28 | O40: US young men | P40: Celebrity reveal | Q40: Big-name guests on stream | R40: Low fit (controversy risk) | S40: Medium | T40: Brand-safety check | U40: Wk3 streamers
...

Sheet Budget Plan
A1: Rate card (vidIQ credits) | B1: Credits
A2: IG profile pull | B2: 5
A3: Short-form watch (TikTok/IG/Shorts) | B3: 10
A4: YouTube transcript | B4: 5
A5: Long-form YouTube watch | B5: 25
A6: Search / outlier call | B6: 5
A7: Monthly cap (Boost plan) | B7: 2000
A8: Buffer to keep untouched | B8: 270
A10: Run (06:00 SGT) | B10: Scope | C10: Creators | D10: IG pulls | E10: Short watches | F10: Transcripts | G10: Long watches | H10: Search calls | I10: Credits | J10: Cumulative | K10: Remaining spendable (cap - buffer)
A11: Run 1 - Sun 11 Oct | B11: Pilot: Jun Yuh, Munya, Night Owl - approve card format | C11: 3 | D11: 3 | E11: 12 | F11: 0 | G11: 0 | H11: 0 | I11: =D11*$B$2+E11*$B$3+F11*$B$4+G11*$B$5+H11*$B$6 -> 135 | J11: =I11 -> 135 | K11: =$B$7-$B$8-J11 -> 1595
A12: Run 2 - Mon 12 Oct | B12: Yapping anchors | C12: 8 | D12: 7 | E12: 32 | F12: 2 | G12: 0 | H12: 0 | I12: =D12*$B$2+E12*$B$3+F12*$B$4+G12*$B$5+H12*$B$6 -> 365 | J12: =J11+I12 -> 500 | K12: =$B$7-$B$8-J12 -> 1230
A13: Run 3 - Tue 13 Oct | B13: Streamers & clip edits | C13: 8 | D13: 0 | E13: 32 | F13: 0 | G13: 0 | H13: 6 | I13: =D13*$B$2+E13*$B$3+F13*$B$4+G13*$B$5+H13*$B$6 -> 350 | J13: =J12+I13 -> 850 | K13: =$B$7-$B$8-J13 -> 880
A14: Run 4 - Wed 14 Oct | B14: Skits + ads anchors | C14: 10 | D14: 8 | E14: 36 | F14: 0 | G14: 2 | H14: 0 | I14: =D14*$B$2+E14*$B$3+F14*$B$4+G14*$B$5+H14*$B$6 -> 450 | J14: =J13+I14 -> 1300 | K14: =$B$7-$B$8-J14 -> 430
A15: Run 5 - Thu 15 Oct | B15: Niche anchors: Pelvic Sanity, Prehab Guys, Sam Sulek | C15: 3 | D15: 3 | E15: 12 | F15: 0 | G15: 0 | H15: 0 | I15: =D15*$B$2+E15*$B$3+F15*$B$4+G15*$B$5+H15*$B$6 -> 135 | J15: =J14+I15 -> 1435 | K15: =$B$7-$B$8-J15 -> 295
A16: Run 6 - Fri 16 Oct | B16: Depth: Dr. Mike, Adam Meakins, Kayla Itsines, Mikayla Nogueira, Frank Body, Scrub Daddy | C16: 6 | D16: 5 | E16: 22 | F16: 1 | G16: 0 | H16: 1 | I16: =D16*$B$2+E16*$B$3+F16*$B$4+G16*$B$5+H16*$B$6 -> 255 | J16: =J15+I16 -> 1690 | K16: =$B$7-$B$8-J16 -> 40
A17: Runs 1-4 | B17: Trend radar (light, 2 calls per run) | C17: 0 | D17: 0 | E17: 0 | F17: 0 | G17: 0 | H17: 8 | I17: =D17*$B$2+E17*$B$3+F17*$B$4+G17*$B$5+H17*$B$6 -> 40 | J17: =J16+I17 -> 1730 | K17: =$B$7-$B$8-J17 -> 0
A18: Total | C18: =SUM(C11:C17) -> 38 | I18: =SUM(I11:I17) -> 1730 | K18: =$B$7-$B$8-I18 -> 0
A19: Buffer check | B19: =IF(I18<=$B$7-$B$8,"OK - buffer of "&$B$8&" preserved","OVER BUDGET") -> OK - buffer of 270 preserved
A20: Note | B20: Unused buffer covers re-watches, your additions, and failed jobs (vidIQ refunds failed analyses). Monthly credits do not roll over - spend gradually, stop at the weekly line.

Sheet Mix Check
A1: Metric | B1: Value | C1: Target
A2: Total creators | B2: =COUNTA('Creator DNA'!$C$2:$C$67) -> 56
A3: US-based | B3: =COUNTIF('Creator DNA'!$D$2:$D$67,"USA") -> 41
A4: US share | B4: =IFERROR(B3/B2,0) -> 0.73214286 | C4: 0.72
A5: Count: Skits / comedy / 2-3 person | B5: =COUNTIFS('Creator DNA'!$B$2:$B$67,"Skits / comedy / 2-3 person",'Creator DNA'!$C$2:$C$67,"<>") -> 12 | C5: 7-12
A6: Count: Ads / UGC / product | B6: =COUNTIFS('Creator DNA'!$B$2:$B$67,"Ads / UGC / product",'Creator DNA'!$C$2:$C$67,"<>") -> 12 | C6: 7-12
A7: Count: Yapping / storytelling / talking-head | B7: =COUNTIFS('Creator DNA'!$B$2:$B$67,"Yapping / storytelling / talking-head",'Creator DNA'!$C$2:$C$67,"<>") -> 12 | C7: 7-12
A8: Count: Streamers & clip edits | B8: =COUNTIFS('Creator DNA'!$B$2:$B$67,"Streamers & clip edits",'Creator DNA'!$C$2:$C$67,"<>") -> 8 | C8: 7-12
A9: Count: Niche / industry | B9: =COUNTIFS('Creator DNA'!$B$2:$B$67,"Niche / industry",'Creator DNA'!$C$2:$C$67,"<>") -> 12 | C9: 7-12
A10: Country: USA | B10: =COUNTIF('Creator DNA'!$D$2:$D$67,"USA") -> 41 | C10: >=1
A11: Country: UK | B11: =COUNTIF('Creator DNA'!$D$2:$D$67,"UK") -> 4 | C11: >=1
A12: Country: Nigeria | B12: =COUNTIF('Creator DNA'!$D$2:$D$67,"Nigeria") -> 1 | C12: >=1
A13: Country: Australia | B13: =COUNTIF('Creator DNA'!$D$2:$D$67,"Australia") -> 2 | C13: >=1
A14: Country: Thailand | B14: =COUNTIF('Creator DNA'!$D$2:$D$67,"Thailand") -> 1 | C14: >=1
A15: Country: Vietnam | B15: =COUNTIF('Creator DNA'!$D$2:$D$67,"Vietnam") -> 1 | C15: >=1
A16: Country: Singapore | B16: =COUNTIF('Creator DNA'!$D$2:$D$67,"Singapore") -> 2 | C16: >=1
A17: Country: Malaysia | B17: =COUNTIF('Creator DNA'!$D$2:$D$67,"Malaysia") -> 2 | C17: >=1
A18: Country: Indonesia | B18: =COUNTIF('Creator DNA'!$D$2:$D$67,"Indonesia") -> 1 | C18: >=1
A19: Low-confidence rows to verify | B19: =COUNTIF('Creator DNA'!$S$2:$S$67,"Low") -> 11

Sheet Legend
A1: Field | B1: Meaning
A2: How to use | B2: Yellow rows at the bottom of 'Creator DNA' are for your additions. Category and Confidence have dropdowns; Energy is 1-5. 'Mix Check' recalculates the US share (target 72%) and country coverage automatically.
A3: Status of this data | B3: DRAFT from published sources + Claude's knowledge, written 11 Oct 2026. Not yet verified by watching videos. Rows marked Low are placeholders - the vidIQ watch pass rewrites them from real footage.
A4: Vibe | B4: The overall feeling in 3-6 words: what it's like to watch.
A5: Tone | B5: Emotional register of the content (deadpan, wholesome, roasting, earnest...).
A6: Energy (1-5) | B6: 1 = slow, calm, cinematic. 5 = loud, chaotic, constant motion.
A7: Pacing & edit | B7: Cut frequency, jump cuts, pauses, B-roll, captions and SFX habits.
A8: Camera & framing | B8: Who holds the camera, angle, shot size, tripod vs handheld, POV.
A9: Lighting & grade | B9: Key light quality and colour grade - feeds straight into Higgsfield prompts.
A10: Voice & delivery | B10: Accent, speed, rhythm, persona, language.
A11: Target age / audience | B11: Who the creator is actually made for: age band, gender skew, region, interest.
A12: Hook pattern | B12: What happens in the first 1-2 seconds.
... A17: Streamers & clip edits | B17: Streamers supply the raw energy; clip EDITORS supply the addictive edit (captions, music, zooms). Both are catalogued.
